{"uuid": "c88de21c-7801-4d79-b95c-c671bdb3d3ad", "children": ["d15ef4cd-1c61-4ccd-ada4-abd727353053"], "befores": [{"name": "suitinit", "status": "broken", "statusDetails": {"message": "selenium.common.exceptions.WebDriverException: Message: An unknown server-side error occurred while processing the command. Original error: Cannot start the 'com.jm.android.jumei' application. Visit https://github.com/appium/appium/blob/master/docs/en/writing-running-appium/android/activity-startup.md for troubleshooting. Original error: Cannot start the 'com.jm.android.jumei' application. Visit https://github.com/appium/appium/blob/master/docs/en/writing-running-appium/android/activity-startup.md for troubleshooting. Original error: Activity name '.com.jm.android.jumei.home.activity.NewHomeActivity' used to start the app doesn't exist or cannot be launched! Make sure it exists and is a launchable activity\n\n", "trace": "  File \"/usr/local/lib/python3.9/site-packages/pluggy/_callers.py\", line 39, in _multicall\n    res = hook_impl.function(*args)\n  File \"/usr/local/lib/python3.9/site-packages/_pytest/fixtures.py\", line 1111, in pytest_fixture_setup\n    result = call_fixture_func(fixturefunc, request, kwargs)\n  File \"/usr/local/lib/python3.9/site-packages/_pytest/fixtures.py\", line 890, in call_fixture_func\n    fixture_result = fixturefunc(**kwargs)\n  File \"/Users/likunyu/project/521-uiautomation/tests/test_suit2/conftest.py\", line 24, in suitinit\n    p.特卖首页.pageinto(action)\n  File \"/Users/likunyu/project/521-uiautomation/lib/pages/productpage.py\", line 27, in pageinto\n    action.start_activity(self.activity)\n  File \"/Users/likunyu/project/521-uiautomation/base/action.py\", line 57, in start_activity\n    self.driver.start_activity(self.env.appium.get(\"appPackage\"), app_activity, **opts)\n  File \"/usr/local/lib/python3.9/site-packages/appium/webdriver/extensions/android/activities.py\", line 63, in start_activity\n    self.execute(Command.START_ACTIVITY, data)\n  File \"/usr/local/lib/python3.9/site-packages/selenium/webdriver/remote/webdriver.py\", line 321, in execute\n    self.error_handler.check_response(response)\n  File \"/usr/local/lib/python3.9/site-packages/appium/webdriver/errorhandler.py\", line 31, in check_response\n    raise wde\n  File \"/usr/local/lib/python3.9/site-packages/appium/webdriver/errorhandler.py\", line 26, in check_response\n    super().check_response(response)\n  File \"/usr/local/lib/python3.9/site-packages/selenium/webdriver/remote/errorhandler.py\", line 242, in check_response\n    raise exception_class(message, screen, stacktrace)\n"}, "start": 1647950468608, "stop": 1647950469413}], "start": 1647950468608, "stop": 1647950469498}