{"uuid": "677459fa-93d4-4537-890c-131e0c8f32c0", "children": ["840ebd49-372c-48c5-ba35-21f149e34af8"], "befores": [{"name": "driverenv", "status": "broken", "statusDetails": {"message": "selenium.common.exceptions.WebDriverException: Message: An unknown server-side error occurred while processing the command. Original error: Could not proxy command to the remote server. Original error: socket hang up\n\n", "trace": "  File \"/usr/local/lib/python3.9/site-packages/pluggy/_callers.py\", line 39, in _multicall\n    res = hook_impl.function(*args)\n  File \"/usr/local/lib/python3.9/site-packages/_pytest/fixtures.py\", line 1111, in pytest_fixture_setup\n    result = call_fixture_func(fixturefunc, request, kwargs)\n  File \"/usr/local/lib/python3.9/site-packages/_pytest/fixtures.py\", line 890, in call_fixture_func\n    fixture_result = fixturefunc(**kwargs)\n  File \"/Users/likunyu/project/521-uiautomation/base/conftest_android.py\", line 45, in driverenv\n    driver = webdriver.Remote(host, capabilities)\n  File \"/usr/local/lib/python3.9/site-packages/appium/webdriver/webdriver.py\", line 267, in __init__\n    super().__init__(\n  File \"/usr/local/lib/python3.9/site-packages/selenium/webdriver/remote/webdriver.py\", line 157, in __init__\n    self.start_session(capabilities, browser_profile)\n  File \"/usr/local/lib/python3.9/site-packages/appium/webdriver/webdriver.py\", line 357, in start_session\n    response = self.execute(RemoteCommand.NEW_SESSION, parameters)\n  File \"/usr/local/lib/python3.9/site-packages/selenium/webdriver/remote/webdriver.py\", line 321, in execute\n    self.error_handler.check_response(response)\n  File \"/usr/local/lib/python3.9/site-packages/selenium/webdriver/remote/errorhandler.py\", line 242, in check_response\n    raise exception_class(message, screen, stacktrace)\n"}, "start": 1653711777122, "stop": 1653711801634}], "start": 1653711777122, "stop": 1653711801699}