{"uuid": "6a1d7fda-ee63-4446-a3b9-ed15b114aee9", "children": ["38108ad9-cf0d-4690-8834-d214329c5900"], "befores": [{"name": "action", "status": "passed", "start": 1653711852548, "stop": 1653711852548}], "afters": [{"name": "action::0", "status": "broken", "statusDetails": {"message": "urllib3.exceptions.MaxRetryError: HTTPConnectionPool(host='127.0.0.1', port=4723): Max retries exceeded with url: /wd/hub/session/c99ab0a4-ec37-4d5b-ad62-5736692d4dc6 (Caused by NewConnectionError('<urllib3.connection.HTTPConnection object at 0x10b203a90>: Failed to establish a new connection: [Errno 61] Connection refused'))\n", "trace": "  File \"/usr/local/lib/python3.9/site-packages/allure_commons/_allure.py\", line 200, in __call__\n    return self._fixture_function(*args, **kwargs)\n  File \"/usr/local/lib/python3.9/site-packages/_pytest/fixtures.py\", line 899, in _teardown_yield_fixture\n    next(it)\n  File \"/Users/likunyu/project/521-uiautomation/base/conftest_android.py\", line 56, in action\n    element_action.driver.quit()\n  File \"/usr/local/lib/python3.9/site-packages/selenium/webdriver/remote/webdriver.py\", line 698, in quit\n    self.execute(Command.QUIT)\n  File \"/usr/local/lib/python3.9/site-packages/selenium/webdriver/remote/webdriver.py\", line 319, in execute\n    response = self.command_executor.execute(driver_command, params)\n  File \"/usr/local/lib/python3.9/site-packages/selenium/webdriver/remote/remote_connection.py\", line 374, in execute\n    return self._request(command_info[0], url, body=data)\n  File \"/usr/local/lib/python3.9/site-packages/selenium/webdriver/remote/remote_connection.py\", line 397, in _request\n    resp = self._conn.request(method, url, body=body, headers=headers)\n  File \"/usr/local/lib/python3.9/site-packages/urllib3/request.py\", line 74, in request\n    return self.request_encode_url(\n  File \"/usr/local/lib/python3.9/site-packages/urllib3/request.py\", line 96, in request_encode_url\n    return self.urlopen(method, url, **extra_kw)\n  File \"/usr/local/lib/python3.9/site-packages/urllib3/poolmanager.py\", line 375, in urlopen\n    response = conn.urlopen(method, u.request_uri, **kw)\n  File \"/usr/local/lib/python3.9/site-packages/urllib3/connectionpool.py\", line 783, in urlopen\n    return self.urlopen(\n  File \"/usr/local/lib/python3.9/site-packages/urllib3/connectionpool.py\", line 783, in urlopen\n    return self.urlopen(\n  File \"/usr/local/lib/python3.9/site-packages/urllib3/connectionpool.py\", line 783, in urlopen\n    return self.urlopen(\n  File \"/usr/local/lib/python3.9/site-packages/urllib3/connectionpool.py\", line 755, in urlopen\n    retries = retries.increment(\n  File \"/usr/local/lib/python3.9/site-packages/urllib3/util/retry.py\", line 574, in increment\n    raise MaxRetryError(_pool, url, error or ResponseError(cause))\n"}, "start": 1653711853696, "stop": 1653711853697}], "start": 1653711852548, "stop": 1653711853697}