{"uuid": "b07cfde6-3396-4290-b2c0-aa2e3e27cd0d", "children": ["33dea1b7-15b9-45ea-bdda-1f80179d4ecc"], "befores": [{"name": "driverenv", "status": "broken", "statusDetails": {"message": "urllib3.exceptions.MaxRetryError: HTTPConnectionPool(host='localhost', port=4723): Max retries exceeded with url: /wd/hub/session (Caused by NewConnectionError('<urllib3.connection.HTTPConnection object at 0x10efc7880>: Failed to establish a new connection: [Errno 61] Connection refused'))\n", "trace": "  File \"/usr/local/lib/python3.9/site-packages/pluggy/_callers.py\", line 39, in _multicall\n    res = hook_impl.function(*args)\n  File \"/usr/local/lib/python3.9/site-packages/_pytest/fixtures.py\", line 1111, in pytest_fixture_setup\n    result = call_fixture_func(fixturefunc, request, kwargs)\n  File \"/usr/local/lib/python3.9/site-packages/_pytest/fixtures.py\", line 890, in call_fixture_func\n    fixture_result = fixturefunc(**kwargs)\n  File \"/Users/likunyu/project/521-uiautomation/base/conftest_android.py\", line 45, in driverenv\n    driver = webdriver.Remote(host, capabilities)\n  File \"/usr/local/lib/python3.9/site-packages/appium/webdriver/webdriver.py\", line 267, in __init__\n    super().__init__(\n  File \"/usr/local/lib/python3.9/site-packages/selenium/webdriver/remote/webdriver.py\", line 157, in __init__\n    self.start_session(capabilities, browser_profile)\n  File \"/usr/local/lib/python3.9/site-packages/appium/webdriver/webdriver.py\", line 357, in start_session\n    response = self.execute(RemoteCommand.NEW_SESSION, parameters)\n  File \"/usr/local/lib/python3.9/site-packages/selenium/webdriver/remote/webdriver.py\", line 319, in execute\n    response = self.command_executor.execute(driver_command, params)\n  File \"/usr/local/lib/python3.9/site-packages/selenium/webdriver/remote/remote_connection.py\", line 374, in execute\n    return self._request(command_info[0], url, body=data)\n  File \"/usr/local/lib/python3.9/site-packages/selenium/webdriver/remote/remote_connection.py\", line 397, in _request\n    resp = self._conn.request(method, url, body=body, headers=headers)\n  File \"/usr/local/lib/python3.9/site-packages/urllib3/request.py\", line 78, in request\n    return self.request_encode_body(\n  File \"/usr/local/lib/python3.9/site-packages/urllib3/request.py\", line 170, in request_encode_body\n    return self.urlopen(method, url, **extra_kw)\n  File \"/usr/local/lib/python3.9/site-packages/urllib3/poolmanager.py\", line 375, in urlopen\n    response = conn.urlopen(method, u.request_uri, **kw)\n  File \"/usr/local/lib/python3.9/site-packages/urllib3/connectionpool.py\", line 783, in urlopen\n    return self.urlopen(\n  File \"/usr/local/lib/python3.9/site-packages/urllib3/connectionpool.py\", line 783, in urlopen\n    return self.urlopen(\n  File \"/usr/local/lib/python3.9/site-packages/urllib3/connectionpool.py\", line 783, in urlopen\n    return self.urlopen(\n  File \"/usr/local/lib/python3.9/site-packages/urllib3/connectionpool.py\", line 755, in urlopen\n    retries = retries.increment(\n  File \"/usr/local/lib/python3.9/site-packages/urllib3/util/retry.py\", line 574, in increment\n    raise MaxRetryError(_pool, url, error or ResponseError(cause))\n"}, "start": 1653711950227, "stop": 1653711950237}], "start": 1653711950227, "stop": 1653711950335}