{"uuid": "35943b66-e571-4404-aca9-6e2510c22b53", "children": ["38108ad9-cf0d-4690-8834-d214329c5900"], "befores": [{"name": "caserun", "status": "passed", "start": 1653711852548, "stop": 1653711852548}], "afters": [{"name": "caserun::0", "status": "broken", "statusDetails": {"message": "urllib3.exceptions.MaxRetryError: HTTPConnectionPool(host='127.0.0.1', port=4723): Max retries exceeded with url: /wd/hub/session/c99ab0a4-ec37-4d5b-ad62-5736692d4dc6/screenshot (Caused by NewConnectionError('<urllib3.connection.HTTPConnection object at 0x10b2bb3a0>: Failed to establish a new connection: [Errno 61] Connection refused'))\n", "trace": "  File \"/usr/local/lib/python3.9/site-packages/allure_commons/_allure.py\", line 200, in __call__\n    return self._fixture_function(*args, **kwargs)\n  File \"/usr/local/lib/python3.9/site-packages/_pytest/fixtures.py\", line 899, in _teardown_yield_fixture\n    next(it)\n  File \"/Users/likunyu/project/521-uiautomation/base/conftest_android.py\", line 64, in caserun\n    action.sleep(1).get_img(\"用例结束前的截图\")\n  File \"/Users/likunyu/project/521-uiautomation/base/action.py\", line 47, in get_img\n    png_data=self.driver.get_screenshot_as_png()\n  File \"/usr/local/lib/python3.9/site-packages/selenium/webdriver/remote/webdriver.py\", line 1064, in get_screenshot_as_png\n    return base64.b64decode(self.get_screenshot_as_base64().encode('ascii'))\n  File \"/usr/local/lib/python3.9/site-packages/selenium/webdriver/remote/webdriver.py\", line 1074, in get_screenshot_as_base64\n    return self.execute(Command.SCREENSHOT)['value']\n  File \"/usr/local/lib/python3.9/site-packages/selenium/webdriver/remote/webdriver.py\", line 319, in execute\n    response = self.command_executor.execute(driver_command, params)\n  File \"/usr/local/lib/python3.9/site-packages/selenium/webdriver/remote/remote_connection.py\", line 374, in execute\n    return self._request(command_info[0], url, body=data)\n  File \"/usr/local/lib/python3.9/site-packages/selenium/webdriver/remote/remote_connection.py\", line 397, in _request\n    resp = self._conn.request(method, url, body=body, headers=headers)\n  File \"/usr/local/lib/python3.9/site-packages/urllib3/request.py\", line 74, in request\n    return self.request_encode_url(\n  File \"/usr/local/lib/python3.9/site-packages/urllib3/request.py\", line 96, in request_encode_url\n    return self.urlopen(method, url, **extra_kw)\n  File \"/usr/local/lib/python3.9/site-packages/urllib3/poolmanager.py\", line 375, in urlopen\n    response = conn.urlopen(method, u.request_uri, **kw)\n  File \"/usr/local/lib/python3.9/site-packages/urllib3/connectionpool.py\", line 783, in urlopen\n    return self.urlopen(\n  File \"/usr/local/lib/python3.9/site-packages/urllib3/connectionpool.py\", line 783, in urlopen\n    return self.urlopen(\n  File \"/usr/local/lib/python3.9/site-packages/urllib3/connectionpool.py\", line 783, in urlopen\n    return self.urlopen(\n  File \"/usr/local/lib/python3.9/site-packages/urllib3/connectionpool.py\", line 755, in urlopen\n    retries = retries.increment(\n  File \"/usr/local/lib/python3.9/site-packages/urllib3/util/retry.py\", line 574, in increment\n    raise MaxRetryError(_pool, url, error or ResponseError(cause))\n"}, "start": 1653711852691, "stop": 1653711853695}], "start": 1653711852548, "stop": 1653711853696}